Workbook

Sheet General Information
D2: Editable cell pl enter details in this color fomatted cell
B5: Section | C5: Item | D5: Details | E5: Developer Notes(If Any)
B6: General Information | C6: Date | D6: 25/1/2024
B7: General Information | C7: Brand Name
B8: General Information | C8: Brand Logo
B9: General Information | C9: Product Name | D9: Other(Provide Name) | E9: Fan
B10: General Information | C10: Product Description
B11: General Information | C11: Firmware version | D11: EFACT V1.2
B12: General Information | C12: Model Name
B13: General Information | C13: Number of pages(Enter the total count of pages in the app) | D13: 1
B14: General Information | C14: page names(List all page names, separated by commas) | D14: Device Configuration
B16: UI TYPE
B18: Name | C18: Sample | D18: Developer Notes(If Any)
B19: Text (Default)
B20: Toggle Switch
B21: Slider
B22: Brightness Slider
B23: CCT Slider
B24: Saturation Slider
B25: Hue Slider
B26: Hue Circle
B27: Push button (Big)
B28: Dropdown
B29: Trigger
B36: DEVICE/PRODUCT
B38: Name | C38: Image | D38: Developer Notes(If Any)
B39: Switch
B40: Lightbulb
B41: Light
B42: Fan
B43: Temperature Sensor
B45: Outlet
B46: Plug
B47: Socket
B48: Lock
B50: Internal Blinds
B52: External Blinds
B54: Garage Door
... B72: Other

Sheet Example Frame 
B1: Operation Name
B2: COMMAND FRAME
B4: Parameter Definition | C4: Parameter Name | D4: Comments | E4: Developer Notes(If Any) | H4: S.No | I4: Start Byte | J4: End Byte | K4: Field Description | L4: Number of Bytes | M4: Bit Size | N4: data type | O4: Value definition | P4: display value (Min) | Q4: display value(Max) | R4: Value in hex(Min) | S4: Value in hex(Max) | T4: UI Type | U4: UI id | V4: UI description in/out | W4: part1 to part2 | X4: Developer Notes(If Any)
B5: Parameter Name | C5: other | D5: =IFERROR(VLOOKUP(C5,HiddenSheet!$H$4:$N$35,7,FALSE()),"") -> Reserved for additional parameters or miscellaneous settings. | E5: Tuning frame | H5: 1 | I5: 1 | J5: 1 | K5: CommandID | L5: 1 | M5: 8 | N5: unsigned int | O5: fixed value | P5: no | Q5: no | R5: A1 | S5: A1
B6: Frame Trigger | C6: Button | D6: =IFERROR(VLOOKUP(C6,HiddenSheet!$B$277:$C$291,2,FALSE()),"") -> The frame is sent when the designated button is pressed. | H6: 2 | I6: 2 | J6: 2 | K6: Function Code | L6: 1 | M6: 8 | N6: unsigned int | O6: fixed value | P6: no | Q6: no | R6: f7 | S6: f7
B7: Frame Type | C7: Command Frame | D7: =IFERROR(VLOOKUP(C7,HiddenSheet!$C$226:$D$268,2,FALSE()),"") -> This frame is a command that can originate from the application, server, or device, used to initiate an action or request information. | E7: part1=app ,part2=device | H7: 3 | I7: 3 | J7: 6 | K7: Data | L7: 4 | M7: 32 | N7: Float | O7: Range value | P7: 0.1 | Q7: 50.0 | R7: 3D CC CC CD | S7: 42 48 00 00 | T7: Text (Default) | U7: 1 | V7: input | X7: resistor
B8: Data Flow Dierection | C8: App or Server to Device | D8: =IFERROR(VLOOKUP(C8,HiddenSheet!$C$256:$D$257,2,FALSE()),"") | H8: 4 | I8: 7 | J8: 10 | K8: Data | L8: 4 | M8: 32 | N8: Float | O8: Range value | P8: 0.002 | Q8: 1.0 | R8: 3b 03 12 6f | S8: 3f800000 | T8: Text (Default) | U8: 2 | V8: input | W8: output | X8: Lmax
B9: Frame Size in Bytes | C9: 34 | D9: Total Number of Bytes in a Frame | H9: 5 | I9: 11 | J9: 14 | K9: Data | L9: 4 | M9: 32 | N9: Float | O9: Range value | P9: 0.002 | Q9: 1 | R9: 3b 03 12 6f | S9: 3f800000 | T9: Text (Default) | U9: 3 | V9: input | W9: output | X9: Lmin
B10: Voice Command | C10: no | D10: This frame includes or is related to a voice command feature. | H10: 6 | I10: 15 | J10: 16 | K10: Data | L10: 2 | M10: 16 | N10: unsigned int | O10: Range value | P10: 5000 | Q10: 25000 | R10: 13 88 | S10: 61 A8 | T10: Text (Default) | U10: 4 | V10: input | W10: output | X10: frequency
B11: Voice Control Instruction Text | D11: Ex:Turn on Fan | H11: 7 | I11: 17 | J11: 17 | K11: Data | L11: 1 | M11: 8 | N11: unsigned int | O11: Range value | P11: 2 | Q11: 40 | R11: 2 | S11: 28 | T11: Text (Default) | U11: 5 | V11: input | W11: output | X11: poles
B12: App Notification | C12: no | D12: This frame triggers a notification in the corresponding application. | H12: 8 | I12: 18 | J12: 21 | K12: Data | L12: 4 | M12: 32 | N12: Float | O12: Range value | P12: 0.01 | Q12: 0.5 | R12: 3a 83 12 6f | S12: 3f 00 00 00 | T12: Text (Default) | U12: 6 | V12: input | W12: output | X12: startupcurrent
H13: 9 | I13: 22 | J13: 25 | K13: Data | L13: 4 | M13: 32 | N13: Float | O13: Range value | P13: 0.2 | Q13: 3 | R13: 3e4ccccd | S13: 40400000 | T13: Text (Default) | U13: 7 | V13: input | W13: output | X13: Max current
H14: 10 | I14: 26 | J14: 27 | K14: Data | L14: 2 | M14: 16 | N14: unsigned int | O14: Range value | P14: 250 | Q14: 300 | R14: fa | S14: 12c | T14: Text (Default) | U14: 8 | V14: input | W14: output | X14: Min rpm
H15: 11 | I15: 28 | J15: 29 | K15: Data | L15: 2 | M15: 16 | N15: unsigned int | O15: Range value | P15: 250 | Q15: 3000 | R15: fa | S15: bb8 | T15: Text (Default) | U15: 9 | V15: input | W15: output | X15: Max rpm
H16: 12 | I16: 30 | J16: 31 | K16: Data | L16: 2 | M16: 16 | N16: unsigned int | O16: Range value | P16: 100 | Q16: 2000 | R16: 64 | S16: 7d0 | T16: Text (Default) | U16: 10 | V16: input | W16: output | X16: CurrentBW
H17: 13 | I17: 32 | J17: 32 | K17: Data | L17: 1 | M17: 8 | N17: unsigned int | O17: Range value | P17: 1 | Q17: 50 | R17: 1 | S17: 32 | T17: Text (Default) | U17: 11 | V17: input | W17: output | X17: bemffreq
H18: 14 | I18: 33 | J18: 33 | K18: Data | L18: 1 | M18: 8 | N18: unsigned int | O18: Range value | P18: 1 | Q18: 40 | R18: 1 | S18: 28 | T18: Text (Default) | U18: 12 | V18: input | W18: output | X18: bemfvoltage
H19: 15 | I19: 34 | J19: 34 | K19: Terminator | L19: 1 | M19: 8 | N19: unsigned int | O19: fixed value | P19: no | Q19: no | R19: 0A | S19: 0A
B66: RESPONSE FRAME
B71: Parameter Definition | C71: Parameter Name | D71: Comments | E71: Developer Notes(If Any) | H71: S.No | I71: Start Byte | J71: End Byte | K71: Number of Bytes | L71: Bit Size | M71: data type | N71: Value definition | O71: Field Description | P71: display value (Min) | Q71: display value(Max) | R71: Value in hex(Min) | S71: Value in hex(Max) | T71: UI Type | U71: UI id | V71: UI description in/out | W71: part1 to part2 | X71: Developer Notes(If Any)
B72: Parameter Name | C72: other | D72: =IFERROR(VLOOKUP(C72,HiddenSheet!$H$4:$N$35,7,FALSE()),"") -> Reserved for additional parameters or miscellaneous settings. | E72: Tuning | H72: 1 | I72: 1 | J72: 1 | K72: 1 | L72: 8 | M72: unsigned int | N72: fixed value | O72: CommandID | P72: no | Q72: no | R72: A1 | S72: A1
B73: Frame Trigger | C73: None | D73: =IFERROR(VLOOKUP(C73,HiddenSheet!$B$277:$C$291,2,FALSE()),"") -> Indicates no user interface element is associated with this parameter, possibly used for internal or system-level parameters not exposed to the user. | H73: 2 | I73: 2 | J73: 2 | K73: 1 | L73: 8 | M73: unsigned int | N73: fixed value | O73: Function Code | P73: no | Q73: no | R73: f7 | S73: f7
B74: Frame Type | C74: Response Frame | D74: =IFERROR(VLOOKUP(C74,HiddenSheet!$C$226:$D$268,2,FALSE()),"") -> This frame is a response from the target of the command, whether it's the device, server, or application, providing confirmation, requested data, or status updates. | E74: part1=device ,part2=app | H74: 3 | I74: 3 | J74: 3 | K74: 4 | L74: 8 | M74: unsigned int | N74: Range value | O74: Data | P74: 0 | Q74: 1 | R74: 0 | S74: 1 | V74: input | X74: 0:failed,1:success
B75: Data Flow Dierection | C75: Device to App or Server | D75: =IFERROR(VLOOKUP(C75,HiddenSheet!$C$256:$D$257,2,FALSE()),"") | H75: 4 | I75: 4 | J75: 4 | K75: 4 | L75: 8 | M75: unsigned int | N75: Range value | O75: Terminator | P75: no | Q75: no | R75: 0A | S75: 0a | V75: input | W75: output
B76: Frame Size in Bytes | C76: 4 | D76: Total Number of Bytes in a Frame
B77: Voice Command | C77: no | D77: This frame includes or is related to a voice command feature.
B78: Voice Control Instruction Text | D78: Ex:Turn on Fan
B79: App Notification | C79: no | D79: This frame triggers a notification in the corresponding application.
B105: ERROR FRAME
B112: Parameter Definition | C112: Parameter Name | D112: Comments | E112: Developer Notes(If Any) | H112: S.No | I112: Start Byte | J112: End Byte | K112: Number of Bytes | L112: Bit Size | M112: data type | N112: Value definition | O112: Description | P112: display value (Min) | Q112: display value(Max) | R112: Value in hex(Min) | S112: Value in hex(Max) | T112: UI Type | U112: UI id | V112: UI description in/out | W112: part1 to part2 | X112: Developer Notes(If Any)
B113: Parameter Name | C113: other | D113: =IFERROR(VLOOKUP(C113,HiddenSheet!$H$4:$N$35,7,FALSE()),"") -> Reserved for additional parameters or miscellaneous settings. | E113: Tuning | H113: 1 | I113: 1 | J113: 1 | K113: 1 | L113: 8 | M113: unsigned int | N113: fixed value | O113: CommandID | P113: no | Q113: no | R113: A1 | S113: A1
B114: Frame Trigger | D114: =IFERROR(VLOOKUP(C114,HiddenSheet!$B$277:$C$291,2,FALSE()),"") | H114: 2 | I114: 2 | J114: 2 | K114: 1 | L114: 8 | M114: unsigned int | N114: fixed value | O114: Function Code | P114: no | Q114: no | R114: f7 | S114: f7
B115: Frame Type | C115: Error Frame | D115: =IFERROR(VLOOKUP(C115,HiddenSheet!$C$226:$D$268,2,FALSE()),"") -> This frame is sent when an error is detected, indicating an issue or exception has occurred, and may include error codes or diagnostic details. It can originate from any participant in the communication process (application, server, or device). | E115: part1=device ,part2=app | H115: 3 | I115: 3 | J115: 3 | K115: 1 | L115: 8 | M115: unsigned int | N115: Range value | O115: Data | P115: no | Q115: no | R115: 0 | S115: ff | U115: 1 | V115: input
B116: Data Flow Dierection | C116: Device to App or Server | D116: =IFERROR(VLOOKUP(C116,HiddenSheet!$C$256:$D$257,2,FALSE()),"") | H116: 4 | I116: 4 | J116: 4 | K116: 1 | L116: 8 | M116: unsigned int | N116: fixed value | O116: Terminator | P116: no | Q116: no | R116: 0a | S116: 0a | U116: 2 | V116: input | W116: output
B117: Frame Size in Bytes | C117: 4 | D117: Total Number of Bytes in a Frame
B118: Voice Command | C118: no | D118: This frame includes or is related to a voice command feature.
B119: Voice Control Instruction Text | D119: Ex:Turn on Fan
B120: App Notification | C120: no | D120: This frame triggers a notification in the corresponding application.

Sheet Voltage
B2: Operation Name | D2: Buzzer | I2: not editable
I3: Editable cell pl enter details in thisfomatted cell
B5: Command FRAME
B7: Parameter Definition | C7: Parameter Name | D7: Comments | E7: Developer Notes(If Any) | G7: S.No | H7: Start Byte position | I7: End Byte position | J7: Field Description | K7: Number of Bytes | L7: Bit Size | M7: data type | N7: Value definition | O7: display value (Min) | P7: display value(Max) | Q7: Value in hex(Min) | R7: Value in hex(Max) | S7: UI Type | T7: UI id | U7: UI Page No | V7: UI description in/out | W7: slider step value | X7: Developer Notes(If Any)
B8: Parameter Name | C8: Voltage | G8: 1 | H8: 1 | I8: 4 | J8: Data | K8: 4 | L8: 32 | M8: Float | N8: Range value | Q8: 0 | R8: FFFFFFFF | S8: Text (Default) | T8: 8 | U8: 1 | V8: Read | X8: voltage
B9: Data Flow Dierection | C9: App/Server to Device | D9: =IFERROR(VLOOKUP(C9,HiddenSheet!$C$256:$D$257,2,FALSE()),"") -> Data is transmitted from the application or server downstream to the device.
B10: Frame Type | C10: Command Frame | D10: =IFERROR(VLOOKUP(C10,HiddenSheet!$C$226:$D$268,2,FALSE()),"") -> This frame is a command that can originate from the application, server, or device, used to initiate an action or request information.
B11: Frame Size in Bytes | C11: 1 | D11: Total Number of Bytes in a Frame
B12: Frame Trigger | C12: incoming frame | D12: =IFERROR(VLOOKUP(C12,HiddenSheet!$B$277:$C$291,2,FALSE()),"") -> An action or sends a frame after it receives a frame.
B13: Multiple UI | C13: =FALSE() -> FALSE
B14: Voice Command | D14: This frame includes or is related to a voice command feature.
B15: Voice Control Instruction Text | D15: Ex:Turn on Fan
B16: App Notification | D16: This frame triggers a notification in the corresponding application.
B69: RESPONSE FRAME
B74: Parameter Definition | C74: Parameter Name | D74: Comments | E74: Developer Notes(If Any) | G74: S.No | H74: Start Byte position | I74: End Byte position | J74: Field Description | K74: Number of Bytes | L74: Bit Size | M74: data type | N74: Value definition | O74: display value (Min) | P74: display value(Max) | Q74: Value in hex(Min) | R74: Value in hex(Max) | S74: UI Type | T74: UI id | U74: UI Page No | V74: UI description in/out | W74: slider step value | X74: Developer Notes(If Any)
B75: Parameter Name | C75: Voltage | D75: =IFERROR(VLOOKUP(C75,HiddenSheet!$H$4:$N$35,7,FALSE()),"")
B76: Data Flow Dierection | C76: Device to App/Server | D76: =IFERROR(VLOOKUP(C76,HiddenSheet!$C$256:$D$257,2,FALSE()),"") -> Data is transmitted from the device upstream to the application or server.
B77: Frame Type | C77: Response Frame | D77: =IFERROR(VLOOKUP(C77,HiddenSheet!$C$226:$D$268,2,FALSE()),"") -> This frame is a response from the target of the command, whether it's the device, server, or application, providing confirmation, requested data, or status updates.
B78: Frame Size in Bytes | C78: 5 | D78: Total Number of Bytes in a Frame
B79: Frame Trigger | C79: Incoming Frame | D79: =IFERROR(VLOOKUP(C79,HiddenSheet!$B$277:$C$291,2,FALSE()),"") -> An action or sends a frame after it receives a frame.
B80: Voice Command | D80: This frame includes or is related to a voice command feature.
B81: Voice Control Instruction Text | D81: Ex:Turn on Fan
B82: App Notification | D82: This frame triggers a notification in the corresponding application.
B108: ERROR FRAME
B115: Parameter Definition | C115: Parameter Name | D115: Comments | E115: Developer Notes(If Any) | G115: S.No | H115: Start Byte position | I115: End Byte position | J115: Field Description | K115: Number of Bytes | L115: Bit Size | M115: data type | N115: Value definition | O115: display value (Min) | P115: display value(Max) | Q115: Value in hex(Min) | R115: Value in hex(Max) | S115: UI Type | T115: UI id | U115: UI Page No | V115: UI description in/out | W115: slider step value | X115: Developer Notes(If Any)
B116: Parameter Name | C116: Voltage | D116: =IFERROR(VLOOKUP(C116,HiddenSheet!$H$4:$N$35,7,FALSE()),"")
B117: Data Flow Dierection | C117: Device to App/Server | D117: =IFERROR(VLOOKUP(C117,HiddenSheet!$C$256:$D$257,2,FALSE()),"") -> Data is transmitted from the device upstream to the application or server.
B118: Frame Type | C118: Error Frame | D118: =IFERROR(VLOOKUP(C118,HiddenSheet!$C$226:$D$268,2,FALSE()),"") -> This frame is sent when an error is detected, indicating an issue or exception has occurred, and may include error codes or diagnostic details. It can originate from any participant in the communication process (application, server, or device).
B119: Frame Size in Bytes | C119: 5 | D119: Total Number of Bytes in a Frame
B120: Frame Trigger | C120: Incoming Frame | D120: =IFERROR(VLOOKUP(C120,HiddenSheet!$B$277:$C$291,2,FALSE()),"") -> An action or sends a frame after it receives a frame.
B121: Voice Command | D121: This frame includes or is related to a voice command feature.
B122: Voice Control Instruction Text | D122: Ex:Turn on Fan
B123: App Notification | D123: This frame triggers a notification in the corresponding application.

Sheet Power
B2: Operation Name | D2: power | I2: not editable
I3: Editable cell pl enter details in thisfomatted cell
B5: Command FRAME
B7: Parameter Definition | C7: Parameter Name | D7: Comments | E7: Developer Notes(If Any) | G7: S.No | H7: Start Byte position | I7: End Byte position | J7: Field Description | K7: Number of Bytes | L7: Bit Size | M7: data type | N7: Value definition | O7: display value (Min) | P7: display value(Max) | Q7: Value in hex(Min) | R7: Value in hex(Max) | S7: UI Type | T7: UI id | U7: UI Page No | V7: UI description in/out | W7: as per ui | X7: as per ui values | Y7: Developer Notes(If Any)
B8: Parameter Name | C8: Power | G8: 1 | H8: 1 | I8: 1 | J8: CommandID | K8: 1 | L8: 8 | M8: unsigned int | N8: fixed value | Q8: A1 | R8: A1
B9: Data Flow Dierection | C9: App/Server to Device | D9: =IFERROR(VLOOKUP(C9,HiddenSheet!$C$256:$D$257,2,FALSE()),"") -> Data is transmitted from the application or server downstream to the device. | G9: 2 | H9: 2 | I9: 2 | J9: Function Code | K9: 1 | L9: 8 | M9: unsigned int | N9: fixed value | Q9: C2 | R9: C2
B10: Frame Type | C10: Command Frame | D10: =IFERROR(VLOOKUP(C10,HiddenSheet!$C$226:$D$268,2,FALSE()),"") -> This frame is a command that can originate from the application, server, or device, used to initiate an action or request information. | G10: 3 | H10: 3 | I10: 3 | J10: Data | K10: 1 | L10: 8 | M10: unsigned int | N10: fixed value | O10: off | P10: on | Q10: 0 | R10: 1 | S10: Toggle Switch | T10: 1 | U10: 1 | V10: Read/Write | W10: [“off”,”on”] | X10: [“00”,”01”] | Y10: 0x00:off,0x01:on
B11: Frame Size in Bytes | C11: 4 | D11: Total Number of Bytes in a Frame | G11: 4 | H11: 4 | I11: 4 | J11: Terminator | K11: 1 | L11: 8 | M11: unsigned int | N11: fixed value | Q11: 0A | R11: 0A
B12: Frame Trigger | C12: Toggle Switch | D12: =IFERROR(VLOOKUP(C12,HiddenSheet!$B$277:$C$291,2,FALSE()),"") -> Allows the user to switch a setting on or off, like a light switch.
B13: Multiple UI | C13: =FALSE() -> FALSE
B14: Voice Command | D14: This frame includes or is related to a voice command feature.
B15: Voice Control Instruction Text | D15: Ex:Turn on Fan
B16: App Notification | D16: This frame triggers a notification in the corresponding application.
B69: RESPONSE FRAME
B74: Parameter Definition | C74: Parameter Name | D74: Comments | E74: Developer Notes(If Any) | G74: S.No | H74: Start Byte position | I74: End Byte position | J74: Field Description | K74: Number of Bytes | L74: Bit Size | M74: data type | N74: Value definition | O74: display value (Min) | P74: display value(Max) | Q74: Value in hex(Min) | R74: Value in hex(Max) | S74: UI Type | T74: UI id | U74: UI Page No | V74: UI description in/out | W74: slider step value | X74: Developer Notes(If Any)
B75: Parameter Name | C75: Switch | D75: =IFERROR(VLOOKUP(C75,HiddenSheet!$H$4:$N$35,7,FALSE()),"")
B76: Data Flow Dierection | C76: Device to App/Server | D76: =IFERROR(VLOOKUP(C76,HiddenSheet!$C$256:$D$257,2,FALSE()),"") -> Data is transmitted from the device upstream to the application or server.
B77: Frame Type | C77: Response Frame | D77: =IFERROR(VLOOKUP(C77,HiddenSheet!$C$226:$D$268,2,FALSE()),"") -> This frame is a response from the target of the command, whether it's the device, server, or application, providing confirmation, requested data, or status updates.
B78: Frame Size in Bytes | C78: 5 | D78: Total Number of Bytes in a Frame
B79: Frame Trigger | C79: Incoming Frame | D79: =IFERROR(VLOOKUP(C79,HiddenSheet!$B$277:$C$291,2,FALSE()),"") -> An action or sends a frame after it receives a frame.
B80: Voice Command | D80: This frame includes or is related to a voice command feature.
B81: Voice Control Instruction Text | D81: Ex:Turn on Fan
B82: App Notification | D82: This frame triggers a notification in the corresponding application.
B108: ERROR FRAME
B115: Parameter Definition | C115: Parameter Name | D115: Comments | E115: Developer Notes(If Any) | G115: S.No | H115: Start Byte position | I115: End Byte position | J115: Field Description | K115: Number of Bytes | L115: Bit Size | M115: data type | N115: Value definition | O115: display value (Min) | P115: display value(Max) | Q115: Value in hex(Min) | R115: Value in hex(Max) | S115: UI Type | T115: UI id | U115: UI Page No | V115: UI description in/out | W115: slider step value | X115: Developer Notes(If Any)
B116: Parameter Name | C116: y | D116: =IFERROR(VLOOKUP(C116,HiddenSheet!$H$4:$N$35,7,FALSE()),"")
B117: Data Flow Dierection | C117: Device to App/Server | D117: =IFERROR(VLOOKUP(C117,HiddenSheet!$C$256:$D$257,2,FALSE()),"") -> Data is transmitted from the device upstream to the application or server.
B118: Frame Type | C118: Error Frame | D118: =IFERROR(VLOOKUP(C118,HiddenSheet!$C$226:$D$268,2,FALSE()),"") -> This frame is sent when an error is detected, indicating an issue or exception has occurred, and may include error codes or diagnostic details. It can originate from any participant in the communication process (application, server, or device).
B119: Frame Size in Bytes | C119: 5 | D119: Total Number of Bytes in a Frame
B120: Frame Trigger | C120: Incoming Frame | D120: =IFERROR(VLOOKUP(C120,HiddenSheet!$B$277:$C$292,2,FALSE()),"") -> An action or sends a frame after it receives a frame.
B121: Voice Command | D121: This frame includes or is related to a voice command feature.
B122: Voice Control Instruction Text | D122: Ex:Turn on Fan
B123: App Notification | D123: This frame triggers a notification in the corresponding application.

Sheet HiddenSheet
B2: Parameter Definition | C2: Parameter Name | H2: Name | I2: Type | J2: DataType | K2: UI Type | L2: Properties | M2: Min, Max, Step | N2: comments
B3: Command Definition | C3: Command ID | D3: A1
B4: Frame Structure | C4: Command Description | D4: Turn on/off | H4: Name | I4: efactor.param.name | J4: String | K4: Default | L4: Read, Write | M4: 1, 32, - | N4: A unique identifier for the device or function.
B5: Data Parsing | C5: Byte Position | D5: 1-2 | H5: Power | I5: efactor.param.power | J5: Bool | K5: efactor.ui.toggle | L5: Read, Write | M5: N/A | N5: A toggle parameter to switch the device power on or off.
B6: Response Structure | C6: Byte Description | D6: Identifies the command | H6: Brightness | I6: efactor.param.brightness | J6: Int | K6: efactor.ui.slider | L6: Read, Write | M6: 0, 100, 1 | N6: Controls the brightness level of the device, with a range from 0 to 100.
B7: Error Handling | C7: Byte Value / Range | D7: A1 | H7: CCT | I7: efactor.param.cct | J7: Int | K7: efactor.ui.slider | L7: Read, Write | M7: 2700, 6500, 100 | N7: Adjusts the color temperature of the light source within the range of 2700K to 6500K.
B8: Developer Notes | C8: Data Type | D8: Hexadecimal | H8: Hue | I8: efactor.param.hue | J8: Int | K8: efactor.ui.slider | L8: Read, Write | M8: 0, 360, 1 | N8: Sets the color hue for lighting, with a possible value from 0 to 360 degrees on the color wheel.
C9: Data Size | D9: 4 bytes | H9: Saturation | I9: efactor.param.saturation | J9: Int | K9: efactor.ui.slider | L9: Read, Write | M9: 0, 100, 1 | N9: Determines the intensity of the color hue from 0 (grey) to 100 (full saturation).
C10: Endianess | D10: Big-endian | H10: Intensity | I10: efactor.param.intensity | J10: Int | K10: efactor.ui.slider | L10: Read, Write | M10: 0, 100, 1 | N10: Regulates the intensity of the signal or light source.
C11: Encoding | D11: ASCII | H11: Speed | I11: efactor.param.speed | J11: Int | K11: efactor.ui.slider | L11: Read, Write | M11: 0, 5, 1 | N11: Adjusts the speed of the device function, within a scale of 0 to 5.
C12: Response ID | D12: A1R | H12: Direction | I12: efactor.param.direction | J12: Int | K12: efactor.ui.dropdown | L12: Read, Write | M12: 0, 1, 1 | N12: Selects the direction of motion or orientation; typically '0' for one direction and '1' for the opposite.
C13: Response Format | D13: Command execution result | H13: Temperature | I13: efactor.param.temperature | J13: Float | K13: Default | L13: Read | M13: N/A | N13: Monitors or sets the temperature; the specific range is not defined here.
C14: Error Codes | D14: E1, E2, E3 | H14: Toggle Controller | I14: efactor.param.toggle | J14: Bool | K14: Any type/Applicable | L14: Read, Write | M14: N/A | N14: A generic toggle switch applicable to various functions.
C15: Error Descriptions | D15: Invalid command, Execution failure, etc. | H15: Range Controller | I15: efactor.param.toggle | J15: Int/Float | K15: Any type/Applicable | L15: Read, Write | M15: App specific | N15: A controller that operates over a specific range, tailored to the application's requirements.
C16: Special Instructions | D16: Checksum calculation details | H16: Mode Controller | I16: efactor.param.mode | J16: String | K16: efactor.ui.dropdown | L16: Read, Write | N16: Allows for the selection of various predefined modes of operation.
C17: Edge Cases | D17: Handling of unexpected values | H17: Setpoint Temperature | I17: efactor.param.setpoint-temperature | J17: Int/Float | K17: Any type/Applicable | L17: Read/Write | M17: N/A | N17: The target temperature for the system to maintain.
C18: Frame Type | H18: Lock State | I18: efactor.param.lockstate | J18: Int | K18: Any type/Applicable | L18: Read, Write | M18: 0, 2, 1 | N18: Indicates or sets the lock state of the device, with '0' for unlocked, '1' for locked, and '2' for jammed or in error.
H19: other | I19: efactor.param.blinds-position | J19: Int | K19: efactor.ui.slider | L19: Read/Write | M19: 0, 100, 1 | N19: Reserved for additional parameters or miscellaneous settings.
H20: Garage Position | I20: efactor.param.garage-position | J20: Int | K20: efactor.ui.slider | L20: Read/Write | M20: 0, 100, 1 | N20: Reflects or controls the position of a garage door, from fully closed (0) to fully open (100).
H21: Light Mode | I21: efactor.param.light-mode | J21: Int | K21: efactor.ui.dropdown | L21: Read/Write | M21: 0, 2, 1 | N21: Specifies the lighting mode, which could include values like '0' for off, '1' for on, or '2' for auto based on ambient conditions.
H22: AC Mode | I22: efactor.paran.ac-mode | J22: String | K22: efactor.ui.dropdown | L22: Read/Write | M22: N/A | N22: Sets the operating mode of the air conditioning system.
H23: Media State | I23: efactor.param.media-activity-state | J23: String | K23: efactor.ui.dropdown | L23: Read/Write | M23: N/A | N23: Represents the current state of a media device, such as playing, paused, or stopped.
H24: Media Control | I24: efactor.param.media-activity-control | J24: String | K24: efactor.ui.dropdown | L24: Read/Write | M24: N/A | N24: Provides control commands for media playback.
H25: Volume | I25: efactor.param.volume | J25: Float | K25: efactor.ui.slider | L25: Read/Write | M25: 0, 20, 1 | N25: Adjusts the volume level from 0 (mute) to 20 (maximum).
H26: Mute | I26: efactor.param.mute | J26: Bool | K26: efactor.ui.toggle | L26: Read/Write | M26: N/A | N26: Toggles the mute state on or off for the device.
H27: App Selector | I27: efactor.param.app-selector | J27: String | K27: efactor.ui.dropdown | L27: Read/Write | M27: N/A | N27: Selects between different application functionalities.
H28: Input Selector | I28: efactor.param.input-selector | J28: String | K28: efactor.ui.dropdown | L28: Read/Write | M28: N/A | N28: Chooses the input source for the device.
H29: Contact Detection State | I29: efactor.param.contact-detection-state | J29: bool | K29: efactor.ui.toggle | L29: Read | M29: N/A | N29: Indicates whether contact has been made or broken, commonly used in security systems.
H30: Motion Detection State | I30: efactor.param.motion-detection-state | J30: bool | K30: efactor.ui.toggle | L30: Read | M30: N/A | N30: Reflects the presence of motion detected by a sensor.
... H35: Burglary Alarm State | I35: efactor.param.burglary-alarm | J35: bool | K35: efactor.ui.toggle | L35: Read | M35: N/A | N35: Indicates the status of the burglary alarm, such as triggered or not triggered.
B53: Byte Position | C53: Byte Description | D53: Data Type | E53: Range
B54: 1 | C54: Identifier for the device or control point | D54: ASCII
B55: 2 | C55: Control or status of the power state (on/off) | D55: Binary
B56: 3 | C56: Adjust the brightness level of a lighting device | D56: Signed Int
B57: 4 | C57: Set or read the color temperature of lighting (measured in Kelvins) | D57: Float
B58: 5 | C58: Adjust the color hue of an RGB lighting device | D58: unsigned int | E58: Parameter ValueRange(Min) | F58: Parameter ValueRange(Max)
B59: 6 | C59: Adjust the color saturation of an RGB lighting device
B60: 7 | C60: Set the intensity of a signal or light
B61: 8 | C61: Control the speed of a device, such as a fan or motor
B62: 9 | C62: Set the direction of movement or operation for a device
...
